<mujoco model="ur10e">
  <compiler angle="radian" meshdir="assets" autolimits="true" />

  <option integrator="implicitfast" />

  <default>
    <default class="ur10e">
      <material specular="0.5" shininess="0.25" />
      <default class="visual">
        <geom type="mesh" contype="0" conaffinity="0" group="2" />
      </default>
      <default class="collision">
        <geom type="capsule" group="3" />
        <default class="eef_collision">
          <geom type="cylinder" />
        </default>
      </default>
      <joint axis="0 1 0" range="-6.28319 6.28319" />
      <default class="joint_limited">
        <joint range="-3.1415 3.1415" />
      </default>
      <default class="position">
        <position ctrlrange="-6.2831 6.2831" kp="2000" kv="200" forcerange="-150 150" />
        <default class="position_limited">
          <position ctrlrange="-3.1415 3.1415" />
        </default>
        <default class="position_small">
          <position kp="500" kv="50" forcerange="-28 28" />
        </default>
      </default>
      <site size="0.001" rgba="0.5 0.5 0.5 0.3" group="4" />
    </default>
  </default>

  <asset>
    <material name="black" rgba="0.033 0.033 0.033 1" />
    <material name="jointgray" rgba="0.278 0.278 0.278 1" />
    <material name="linkgray" rgba="0.82 0.82 0.82 1" />
    <material name="urblue" rgba="0.49 0.678 0.8 1" />

    <mesh file="base_0.obj" />
    <mesh file="base_1.obj" />
    <mesh file="shoulder_0.obj" />
    <mesh file="shoulder_1.obj" />
    <mesh file="shoulder_2.obj" />
    <mesh file="upperarm_0.obj" />
    <mesh file="upperarm_1.obj" />
    <mesh file="upperarm_2.obj" />
    <mesh file="upperarm_3.obj" />
    <mesh file="forearm_0.obj" />
    <mesh file="forearm_1.obj" />
    <mesh file="forearm_2.obj" />
    <mesh file="forearm_3.obj" />
    <mesh file="wrist1_0.obj" />
    <mesh file="wrist1_1.obj" />
    <mesh file="wrist1_2.obj" />
    <mesh file="wrist2_0.obj" />
    <mesh file="wrist2_1.obj" />
    <mesh file="wrist2_2.obj" />
    <mesh file="wrist3.obj" />
  </asset>

  <worldbody>
    <body name="base" quat="1 0 0 1" childclass="ur10e">
      <inertial mass="4" pos="0 0 0" diaginertia="0.0061063308908 0.0061063308908 0.01125" />
      <geom mesh="base_0" material="black" class="visual" />
      <geom mesh="base_1" material="linkgray" class="visual" />
      <body name="shoulder_link" pos="0 0 0.181">
        <inertial mass="7.778" pos="0 0 0" diaginertia="0.0314743 0.0314743 0.0218756" />
        <joint name="shoulder_pan" axis="0 0 1" />
        <site name="shoulder_pan" />
        <geom mesh="shoulder_0" material="urblue" class="visual" />
        <geom mesh="shoulder_1" material="black" class="visual" />
        <geom mesh="shoulder_2" material="jointgray" class="visual" />
        <geom class="collision" size="0.078 0.08" pos="0 0 -0.05" />
        <body name="upper_arm_link" pos="0 0.176 0" quat="1 0 1 0">
          <inertial mass="12.93" pos="0 0 0.3065"
            diaginertia="0.423074 0.423074 0.0363656" />
          <joint name="shoulder_lift" />
          <site name="shoulder_lift" />
          <geom mesh="upperarm_0" material="black" class="visual" />
          <geom mesh="upperarm_1" material="jointgray" class="visual" />
          <geom mesh="upperarm_2" material="urblue" class="visual" />
          <geom mesh="upperarm_3" material="linkgray" class="visual" />
          <geom class="collision" pos="0 -0.05 0" quat="1 1 0 0" size="0.078 0.08" />
          <geom class="collision" size="0.06 0.3" pos="0 0 0.3" />
          <body name="forearm_link" pos="0 -0.137 0.613">
            <inertial mass="3.87" pos="0 0 0.2855"
              diaginertia="0.11059 0.11059 0.0108844" />
            <joint name="elbow" class="joint_limited" />
            <site name="elbow" />
            <geom mesh="forearm_0" material="urblue" class="visual" />
            <geom mesh="forearm_1" material="black" class="visual" />
            <geom mesh="forearm_2" material="jointgray" class="visual" />
            <geom mesh="forearm_3" material="linkgray" class="visual" />
            <geom class="collision" pos="0 0.08 0" quat="1 1 0 0" size="0.058 0.065" />
            <geom class="collision" size="0.043 0.28" pos="0 0 0.29" />
            <body name="wrist_1_link" pos="0 0 0.571" quat="1 0 1 0">
              <inertial mass="1.96" pos="0 0.135 0"
                diaginertia="0.0055125 0.00510825 0.00510825" />
              <joint name="wrist_1" />
              <site name="wrist_1" />
              <geom mesh="wrist1_0" material="black" class="visual" />
              <geom mesh="wrist1_1" material="urblue" class="visual" />
              <geom mesh="wrist1_2" material="jointgray" class="visual" />
              <geom class="collision" pos="0 0.06 0" quat="1 1 0 0" size="0.05 0.07" />
              <body name="wrist_2_link" pos="0 0.135 0">
                <inertial mass="1.96" pos="0 0 0.12"
                  diaginertia="0.0055125 0.00510825 0.00510825" />
                <joint name="wrist_2" axis="0 0 1" />
                <site name="wrist_2" />
                <geom mesh="wrist2_0" material="black" class="visual" />
                <geom mesh="wrist2_1" material="urblue" class="visual" />
                <geom mesh="wrist2_2" material="jointgray" class="visual" />
                <geom class="collision" size="0.046 0.065" pos="0 0 0.05" />
                <geom class="collision" pos="0 0.028 0.12" quat="1 1 0 0"
                  size="0.046 0.043" />
                <body name="wrist_3_link" pos="0 0 0.12">
                  <inertial mass="0.202" pos="0 0.092 0" quat="0 1 -1 0"
                    diaginertia="0.000204525 0.000144346 0.000144346" />
                  <joint name="wrist_3" />
                  <geom material="linkgray" mesh="wrist3" class="visual" />
                  <geom class="eef_collision" pos="0 0.097 0" quat="1 1 0 0"
                    size="0.046 0.02" />
                  <body name="tool_link" pos="0 0.1 0" quat="-1 1 0 0">
                    <site name="attachment_site" rgba="1 0 0 1" size="0.01" />
                    <site name="eef_site" pos="0 0 0.05"
                      quat="0 0.7071068 -0.7071068 0" />
                  </body>
                </body>
              </body>
            </body>
          </body>
        </body>
      </body>
    </body>
  </worldbody>

  <!-- <actuator> -->
  <!-- <general class="position" name="shoulder_pan" joint="shoulder_pan" />
    <general class="position" name="shoulder_lift" joint="shoulder_lift" />
    <general class="position_limited" name="elbow" joint="elbow" />
    <general class="position_small" name="wrist_1" joint="wrist_1" />
    <general class="position_small" name="wrist_2" joint="wrist_2" />
    <general class="position_small" name="wrist_3" joint="wrist_3" /> -->
  <!-- </actuator> -->

  <!-- <keyframe>
    <key name="home" qpos="-1.5708 -1.5708 1.5708 -1.5708 -1.5708 0"
      ctrl="-1.5708 -1.5708 1.5708 -1.5708 -1.5708 0" />
  </keyframe> -->
</mujoco>